Workbook

Sheet По неделям
A1: № нед. | B1: Неделя | C1: Тема недели (конспект) | D1: Компас, ср: дата | E1: Ср: урок № | F1: Ср: что | G1: Компас, пт: дата | H1: Пт: урок № | I1: Пт: что | J1: ФШ онлайн, пн: дата | K1: Пн: урок № | L1: Пн: что
A2: 1 | B2: 19.10–25.10 | C2: К1. Алгоритмы и исполнители. Свойства алгоритмов | D2: 46316 | E2: 7 | F2: К1 | G2: 46318 | H2: 7 | I2: К1 | J2: 46314 | K2: 6 | L2: К1
A3: 2 | B3: 26.10–01.11 | C3: К2. Способы записи алгоритмов. Блок-схемы. Среда Python | D3: 46323 | E3: 8 | F3: К2 | G3: 46325 | H3: 8 | I3: К2 | J3: 46321 | K3: 7 | L3: К2
A4: 3 | B4: 02.11–08.11 | C4: (у Компаса нет урока) | F4: — | I4: — | J4: 46328 | K4: 8 | L4: Практикум
A5: 4 | B5: 09.11–15.11 | C5: К3. Исполнитель «Черепаха» (turtle). Линейный алгоритм | D5: 46337 | E5: 9 | F5: К3 | I5: — | J5: 46335 | K5: 9 | L5: К3
A6: 5 | B6: 16.11–22.11 | C6: Пром. аттестация 1 | D6: 46344 | E6: 10 | F6: Пром. аттестация 1 | G6: 46346 | H6: 9 | I6: Пром. аттестация 1 | L6: —
A7: 6 | B7: 23.11–29.11 | C7: Пром. аттестация 2 | D7: 46351 | E7: 11 | F7: Пром. аттестация 2 | G7: 46353 | H7: 10 | I7: Пром. аттестация 2 | J7: 46349 | K7: 10 | L7: Практикум
A8: 7 | B8: 30.11–06.12 | C8: Пром. аттестация 3 | D8: 46358 | E8: 12 | F8: Пром. аттестация 3 | G8: 46360 | H8: 11 | I8: К4 | J8: 46356 | K8: 11 | L8: Практикум
A9: 8 | B9: 07.12–13.12 | C9: К4. Величины и присваивание. Переменные | D9: 46365 | E9: 13 | F9: К4 | G9: 46367 | H9: 12 | I9: К5 | J9: 46363 | K9: 12 | L9: К4
A10: 9 | B10: 14.12–20.12 | C10: К5. Ввод и вывод данных. Типы данных | D10: 46372 | E10: 14 | F10: К5 | G10: 46374 | H10: 13 | I10: К6 | J10: 46370 | K10: 13 | L10: К5
A11: 10 | B11: 21.12–27.12 | C11: К6. Линейные программы. Арифметические операции | D11: 46379 | E11: 15 | F11: К6 | I11: — | J11: 46377 | K11: 14 | L11: К6
A12: 11 | B12: 28.12–03.01 | C12: (у Компаса нет урока) | F12: — | I12: — | J12: 46384 | K12: 15 | L12: Практикум
A13: 12 | B13: 04.01–10.01 | C13: Каникулы у всех | F13: — | I13: — | L13: —
A14: 13 | B14: 11.01–17.01 | C14: К7. Целочисленное деление // и %. Практикум | D14: 46400 | E14: 16 | F14: К7 | G14: 46402 | H14: 14 | I14: К7 | J14: 46398 | K14: 16 | L14: К7
A15: 14 | B15: 18.01–24.01 | C15: К8. Ветвление. Полная форма: if / else | D15: 46407 | E15: 17 | F15: К8 | G15: 46409 | H15: 15 | I15: К8 | J15: 46405 | K15: 17 | L15: К8
A16: 15 | B16: 25.01–31.01 | C16: К9. Логика 1. Высказывания. Операции НЕ, И, ИЛИ | D16: 46414 | E16: 18 | F16: К9 | G16: 46416 | H16: 16 | I16: К9 | J16: 46412 | K16: 18 | L16: К9
A17: 16 | B17: 01.02–07.02 | C17: К10. Логика 2. Логические выражения. Приоритет операций | D17: 46421 | E17: 19 | F17: К10 | G17: 46423 | H17: 17 | I17: К10 | J17: 46419 | K17: 19 | L17: К10
A18: 17 | B18: 08.02–14.02 | C18: К11. Логика 3. Таблицы истинности. Логические элементы | D18: 46428 | E18: 20 | F18: К11 | G18: 46430 | H18: 18 | I18: К11 | J18: 46426 | K18: 20 | L18: К11
A19: 18 | B19: 15.02–21.02 | C19: К12. Неполное ветвление. Сложные условия: and, or, not | D19: 46435 | E19: 21 | F19: К12 | G19: 46437 | H19: 19 | I19: К12 | J19: 46433 | K19: 21 | L19: К12
A20: 19 | B20: 22.02–28.02 | C20: К13. Выбор из нескольких вариантов: elif | D20: 46442 | E20: 22 | F20: К13 | G20: 46444 | H20: 20 | I20: К13 | L20: —
A21: 20 | B21: 01.03–07.03 | C21: (у Компаса нет урока) | F21: — | I21: — | J21: 46447 | K21: 22 | L21: К13
A22: 21 | B22: 08.03–14.03 | C22: К14. Практикум + проверочная работа по ветвлениям | D22: 46456 | E22: 23 | F22: К14 | G22: 46458 | H22: 21 | I22: К14 | L22: —
A23: 22 | B23: 15.03–21.03 | C23: К15. Цикл с заданным числом повторений и с переменной: for, range | D23: 46463 | E23: 24 | F23: К15 | G23: 46465 | H23: 22 | I23: К15 | J23: 46461 | K23: 23 | L23: К14
A24: 23 | B24: 22.03–28.03 | C24: К16. Сумма и счётчик в цикле | D24: 46470 | E24: 25 | F24: К16 | G24: 46472 | H24: 23 | I24: К16 | J24: 46468 | K24: 24 | L24: К15
A25: 24 | B25: 29.03–04.04 | C25: К17. Цикл с условием продолжения: while | D25: 46477 | E25: 26 | F25: К17 | G25: 46479 | H25: 24 | I25: К17 | J25: 46475 | K25: 25 | L25: К16
A26: 25 | B26: 05.04–11.04 | C26: К18. Цикл с условием окончания: while True + break | D26: 46484 | E26: 27 | F26: К18 | G26: 46486 | H26: 25 | I26: К18 | L26: —
A27: 26 | B27: 12.04–18.04 | C27: Год. аттестация 1 | D27: 46491 | E27: 28 | F27: Год. аттестация 1 | G27: 46493 | H27: 26 | I27: Год. аттестация 1 | J27: 46489 | K27: 26 | L27: К17
A28: 27 | B28: 19.04–25.04 | C28: Год. аттестация 2 | D28: 46498 | E28: 29 | F28: Год. аттестация 2 | G28: 46500 | H28: 27 | I28: Год. аттестация 2 | J28: 46496 | K28: 27 | L28: К18
A29: 28 | B29: 26.04–02.05 | C29: Год. аттестация 3 | D29: 46505 | E29: 30 | F29: Год. аттестация 3 | I29: — | J29: 46503 | K29: 28 | L29: К19
A30: 29 | B30: 03.05–09.05 | C30: К19. Цикл + ветвление. Задачи в формате ОГЭ | D30: 46512 | E30: 31 | F30: К19 | G30: 46514 | H30: 28 | I30: К19 | L30: —
A31: 30 | B31: 10.05–16.05 | C31: К20. Итоговая работа | D31: 46519 | E31: 32 | F31: К20 | G31: 46521 | H31: 29 | I31: К20 | L31: —
A32: 31 | B32: 17.05–23.05 | C32: Обобщение курса | D32: 46526 | E32: 33 | F32: Обобщение курса | I32: — | J32: 46524 | K32: 29 | L32: К20
A33: 32 | B33: 24.05–30.05 | C33: Резерв | D33: 46533 | E33: 34 | F33: Резерв | I33: — | J33: 46531 | K33: 30 | L33: Обобщение курса
A34: 33 | B34: 31.05–06.06 | C34: (у Компаса нет урока) | F34: — | I34: — | J34: 46538 | K34: 31 | L34: Резерв
A36: Обозначения:
A37: Серым — у группы нет урока на этой неделе (каникулы / неучебный день).
A38: Жёлтым — группа проходит другую тему, чем среда на этой неделе (опережает или отстаёт на 1 тему); конспект тот же, из общего комплекта.
A39: Зелёным — у группы на этой неделе практикум/резерв вместо темы среды или аттестации.
A40: К1–К20 — номера конспектов; названия на листе «Конспекты».
A41: Номера уроков по журналу: Компас — продолжение с урока 7 (6 уже проведено), ФШ — с урока 6 (предположение: 5 уроков проведено, первый урок 07.09).
...

Sheet Конспекты
A1: № | B1: Тема | C1: Компас, ср | D1: Компас, пт | E1: ФШ, пн
A2: К1 | B2: Алгоритмы и исполнители. Свойства алгоритмов | C2: =IFERROR(INDEX('По неделям'!$D$2:$D$34,MATCH("К1",'По неделям'!$F$2:$F$34,0)),"не проходит") -> 46316 | D2: =IFERROR(INDEX('По неделям'!$G$2:$G$34,MATCH("К1",'По неделям'!$I$2:$I$34,0)),"не проходит") -> 46318 | E2: =IFERROR(INDEX('По неделям'!$J$2:$J$34,MATCH("К1",'По неделям'!$L$2:$L$34,0)),"не проходит") -> 46314
A3: К2 | B3: Способы записи алгоритмов. Блок-схемы. Среда Python | C3: =IFERROR(INDEX('По неделям'!$D$2:$D$34,MATCH("К2",'По неделям'!$F$2:$F$34,0)),"не проходит") -> 46323 | D3: =IFERROR(INDEX('По неделям'!$G$2:$G$34,MATCH("К2",'По неделям'!$I$2:$I$34,0)),"не проходит") -> 46325 | E3: =IFERROR(INDEX('По неделям'!$J$2:$J$34,MATCH("К2",'По неделям'!$L$2:$L$34,0)),"не проходит") -> 46321
A4: К3 | B4: Исполнитель «Черепаха» (turtle). Линейный алгоритм | C4: =IFERROR(INDEX('По неделям'!$D$2:$D$34,MATCH("К3",'По неделям'!$F$2:$F$34,0)),"не проходит") -> 46337 | D4: =IFERROR(INDEX('По неделям'!$G$2:$G$34,MATCH("К3",'По неделям'!$I$2:$I$34,0)),"не проходит") -> не проходит | E4: =IFERROR(INDEX('По неделям'!$J$2:$J$34,MATCH("К3",'По неделям'!$L$2:$L$34,0)),"не проходит") -> 46335
A5: К4 | B5: Величины и присваивание. Переменные | C5: =IFERROR(INDEX('По неделям'!$D$2:$D$34,MATCH("К4",'По неделям'!$F$2:$F$34,0)),"не проходит") -> 46365 | D5: =IFERROR(INDEX('По неделям'!$G$2:$G$34,MATCH("К4",'По неделям'!$I$2:$I$34,0)),"не проходит") -> 46360 | E5: =IFERROR(INDEX('По неделям'!$J$2:$J$34,MATCH("К4",'По неделям'!$L$2:$L$34,0)),"не проходит") -> 46363
A6: К5 | B6: Ввод и вывод данных. Типы данных | C6: =IFERROR(INDEX('По неделям'!$D$2:$D$34,MATCH("К5",'По неделям'!$F$2:$F$34,0)),"не проходит") -> 46372 | D6: =IFERROR(INDEX('По неделям'!$G$2:$G$34,MATCH("К5",'По неделям'!$I$2:$I$34,0)),"не проходит") -> 46367 | E6: =IFERROR(INDEX('По неделям'!$J$2:$J$34,MATCH("К5",'По неделям'!$L$2:$L$34,0)),"не проходит") -> 46370
A7: К6 | B7: Линейные программы. Арифметические операции | C7: =IFERROR(INDEX('По неделям'!$D$2:$D$34,MATCH("К6",'По неделям'!$F$2:$F$34,0)),"не проходит") -> 46379 | D7: =IFERROR(INDEX('По неделям'!$G$2:$G$34,MATCH("К6",'По неделям'!$I$2:$I$34,0)),"не проходит") -> 46374 | E7: =IFERROR(INDEX('По неделям'!$J$2:$J$34,MATCH("К6",'По неделям'!$L$2:$L$34,0)),"не проходит") -> 46377
A8: К7 | B8: Целочисленное деление // и %. Практикум | C8: =IFERROR(INDEX('По неделям'!$D$2:$D$34,MATCH("К7",'По неделям'!$F$2:$F$34,0)),"не проходит") -> 46400 | D8: =IFERROR(INDEX('По неделям'!$G$2:$G$34,MATCH("К7",'По неделям'!$I$2:$I$34,0)),"не проходит") -> 46402 | E8: =IFERROR(INDEX('По неделям'!$J$2:$J$34,MATCH("К7",'По неделям'!$L$2:$L$34,0)),"не проходит") -> 46398
A9: К8 | B9: Ветвление. Полная форма: if / else | C9: =IFERROR(INDEX('По неделям'!$D$2:$D$34,MATCH("К8",'По неделям'!$F$2:$F$34,0)),"не проходит") -> 46407 | D9: =IFERROR(INDEX('По неделям'!$G$2:$G$34,MATCH("К8",'По неделям'!$I$2:$I$34,0)),"не проходит") -> 46409 | E9: =IFERROR(INDEX('По неделям'!$J$2:$J$34,MATCH("К8",'По неделям'!$L$2:$L$34,0)),"не проходит") -> 46405
A10: К9 | B10: Логика 1. Высказывания. Операции НЕ, И, ИЛИ | C10: =IFERROR(INDEX('По неделям'!$D$2:$D$34,MATCH("К9",'По неделям'!$F$2:$F$34,0)),"не проходит") -> 46414 | D10: =IFERROR(INDEX('По неделям'!$G$2:$G$34,MATCH("К9",'По неделям'!$I$2:$I$34,0)),"не проходит") -> 46416 | E10: =IFERROR(INDEX('По неделям'!$J$2:$J$34,MATCH("К9",'По неделям'!$L$2:$L$34,0)),"не проходит") -> 46412
A11: К10 | B11: Логика 2. Логические выражения. Приоритет операций | C11: =IFERROR(INDEX('По неделям'!$D$2:$D$34,MATCH("К10",'По неделям'!$F$2:$F$34,0)),"не проходит") -> 46421 | D11: =IFERROR(INDEX('По неделям'!$G$2:$G$34,MATCH("К10",'По неделям'!$I$2:$I$34,0)),"не проходит") -> 46423 | E11: =IFERROR(INDEX('По неделям'!$J$2:$J$34,MATCH("К10",'По неделям'!$L$2:$L$34,0)),"не проходит") -> 46419
A12: К11 | B12: Логика 3. Таблицы истинности. Логические элементы | C12: =IFERROR(INDEX('По неделям'!$D$2:$D$34,MATCH("К11",'По неделям'!$F$2:$F$34,0)),"не проходит") -> 46428 | D12: =IFERROR(INDEX('По неделям'!$G$2:$G$34,MATCH("К11",'По неделям'!$I$2:$I$34,0)),"не проходит") -> 46430 | E12: =IFERROR(INDEX('По неделям'!$J$2:$J$34,MATCH("К11",'По неделям'!$L$2:$L$34,0)),"не проходит") -> 46426
A13: К12 | B13: Неполное ветвление. Сложные условия: and, or, not | C13: =IFERROR(INDEX('По неделям'!$D$2:$D$34,MATCH("К12",'По неделям'!$F$2:$F$34,0)),"не проходит") -> 46435 | D13: =IFERROR(INDEX('По неделям'!$G$2:$G$34,MATCH("К12",'По неделям'!$I$2:$I$34,0)),"не проходит") -> 46437 | E13: =IFERROR(INDEX('По неделям'!$J$2:$J$34,MATCH("К12",'По неделям'!$L$2:$L$34,0)),"не проходит") -> 46433
A14: К13 | B14: Выбор из нескольких вариантов: elif | C14: =IFERROR(INDEX('По неделям'!$D$2:$D$34,MATCH("К13",'По неделям'!$F$2:$F$34,0)),"не проходит") -> 46442 | D14: =IFERROR(INDEX('По неделям'!$G$2:$G$34,MATCH("К13",'По неделям'!$I$2:$I$34,0)),"не проходит") -> 46444 | E14: =IFERROR(INDEX('По неделям'!$J$2:$J$34,MATCH("К13",'По неделям'!$L$2:$L$34,0)),"не проходит") -> 46447
A15: К14 | B15: Практикум + проверочная работа по ветвлениям | C15: =IFERROR(INDEX('По неделям'!$D$2:$D$34,MATCH("К14",'По неделям'!$F$2:$F$34,0)),"не проходит") -> 46456 | D15: =IFERROR(INDEX('По неделям'!$G$2:$G$34,MATCH("К14",'По неделям'!$I$2:$I$34,0)),"не проходит") -> 46458 | E15: =IFERROR(INDEX('По неделям'!$J$2:$J$34,MATCH("К14",'По неделям'!$L$2:$L$34,0)),"не проходит") -> 46461
A16: К15 | B16: Цикл с заданным числом повторений и с переменной: for, range | C16: =IFERROR(INDEX('По неделям'!$D$2:$D$34,MATCH("К15",'По неделям'!$F$2:$F$34,0)),"не проходит") -> 46463 | D16: =IFERROR(INDEX('По неделям'!$G$2:$G$34,MATCH("К15",'По неделям'!$I$2:$I$34,0)),"не проходит") -> 46465 | E16: =IFERROR(INDEX('По неделям'!$J$2:$J$34,MATCH("К15",'По неделям'!$L$2:$L$34,0)),"не проходит") -> 46468
A17: К16 | B17: Сумма и счётчик в цикле | C17: =IFERROR(INDEX('По неделям'!$D$2:$D$34,MATCH("К16",'По неделям'!$F$2:$F$34,0)),"не проходит") -> 46470 | D17: =IFERROR(INDEX('По неделям'!$G$2:$G$34,MATCH("К16",'По неделям'!$I$2:$I$34,0)),"не проходит") -> 46472 | E17: =IFERROR(INDEX('По неделям'!$J$2:$J$34,MATCH("К16",'По неделям'!$L$2:$L$34,0)),"не проходит") -> 46475
A18: К17 | B18: Цикл с условием продолжения: while | C18: =IFERROR(INDEX('По неделям'!$D$2:$D$34,MATCH("К17",'По неделям'!$F$2:$F$34,0)),"не проходит") -> 46477 | D18: =IFERROR(INDEX('По неделям'!$G$2:$G$34,MATCH("К17",'По неделям'!$I$2:$I$34,0)),"не проходит") -> 46479 | E18: =IFERROR(INDEX('По неделям'!$J$2:$J$34,MATCH("К17",'По неделям'!$L$2:$L$34,0)),"не проходит") -> 46489
A19: К18 | B19: Цикл с условием окончания: while True + break | C19: =IFERROR(INDEX('По неделям'!$D$2:$D$34,MATCH("К18",'По неделям'!$F$2:$F$34,0)),"не проходит") -> 46484 | D19: =IFERROR(INDEX('По неделям'!$G$2:$G$34,MATCH("К18",'По неделям'!$I$2:$I$34,0)),"не проходит") -> 46486 | E19: =IFERROR(INDEX('По неделям'!$J$2:$J$34,MATCH("К18",'По неделям'!$L$2:$L$34,0)),"не проходит") -> 46496
A20: К19 | B20: Цикл + ветвление. Задачи в формате ОГЭ | C20: =IFERROR(INDEX('По неделям'!$D$2:$D$34,MATCH("К19",'По неделям'!$F$2:$F$34,0)),"не проходит") -> 46512 | D20: =IFERROR(INDEX('По неделям'!$G$2:$G$34,MATCH("К19",'По неделям'!$I$2:$I$34,0)),"не проходит") -> 46514 | E20: =IFERROR(INDEX('По неделям'!$J$2:$J$34,MATCH("К19",'По неделям'!$L$2:$L$34,0)),"не проходит") -> 46503
A21: К20 | B21: Итоговая работа | C21: =IFERROR(INDEX('По неделям'!$D$2:$D$34,MATCH("К20",'По неделям'!$F$2:$F$34,0)),"не проходит") -> 46519 | D21: =IFERROR(INDEX('По неделям'!$G$2:$G$34,MATCH("К20",'По неделям'!$I$2:$I$34,0)),"не проходит") -> 46521 | E21: =IFERROR(INDEX('По неделям'!$J$2:$J$34,MATCH("К20",'По неделям'!$L$2:$L$34,0)),"не проходит") -> 46524
B23: Всего уроков с 19.10 | C23: =COUNTIF('По неделям'!F2:F34,"<>—") -> 28 | D23: =COUNTIF('По неделям'!I2:I34,"<>—") -> 23 | E23: =COUNTIF('По неделям'!L2:L34,"<>—") -> 26
B24: Пройдено тем К1–К20 | C24: =COUNTIF('По неделям'!F2:F34,"К*") -> 20 | D24: =COUNTIF('По неделям'!I2:I34,"К*") -> 19 | E24: =COUNTIF('По неделям'!L2:L34,"К*") -> 20
